Workbook

Sheet Charts

Sheet Combined Data
A2: Week # | B2: 2023 | C2: 2024 | D2: 2025 | E2: 2026 | F2: Previous Year % Change | G2: Miles 2026 | H2: Revenue Per Mile 2026 | I2: Revenue Per Truck 2026 | J2: Utilization %
A3: W01 | B3: 3718.75 | C3: 88296.61 | D3: 146998.6 | E3: 114901.17 | F3: -0.2184 | G3: 26150.44 | H3: =E3/G3 -> 4.3938523 | I3: =E3/32 -> 3590.6616 | J3: 0.37
A4: W02 | B4: 77590.58 | C4: 126978.65 | D4: 165902.35 | E4: 175316.39 | F4: 0.0567 | G4: 38641.74 | H4: =E4/G4 -> 4.5369693 | I4: =E4/32 -> 5478.6372 | J4: 0.52
A5: W03 | B5: 85440.26 | C5: 118982.09 | D5: 158181.09 | E5: 253843.56 | F5: 0.6048 | G5: 44630.37 | H5: =E5/G5 -> 5.6876867 | I5: =E5/32 -> 7932.6112 | J5: 0.63
A6: W04 | B6: 96081.51 | C6: 118903.61 | D6: 145399.18 | E6: 231385.31 | F6: 0.5914 | G6: 47958.86 | H6: =E6/G6 -> 4.8246624 | I6: =E6/32 -> 7230.7909 | J6: 0.71
A7: W05 | B7: 80816.82 | C7: 140190.75 | D7: 188231.53 | E7: 243852.47 | F7: 0.2955 | G7: 46459.21 | H7: =E7/G7 -> 5.2487434 | I7: =E7/32 -> 7620.3897 | J7: 0.72
A8: W06 | B8: 73017.07 | C8: 144552.29 | D8: 149220.7 | E8: 237229.39 | F8: 0.5898 | G8: 50715.14 | H8: =E8/G8 -> 4.6776838 | I8: =E8/32 -> 7413.4184 | J8: 0.79
A9: W07 | B9: 82108.13 | C9: 106451.51 | D9: 153156.54 | E9: 249988.92 | F9: 0.6322 | G9: 52021.44 | H9: =E9/G9 -> 4.8054979 | I9: =E9/32 -> 7812.1538 | J9: 0.52
A10: W08 | B10: 77806.5 | C10: 121868.36 | D10: 171482.25 | E10: 209611.35 | F10: 0.2224 | G10: 48223.569 | H10: =E10/G10 -> 4.3466578 | I10: =E10/32 -> 6550.3547 | J10: 0.55
A11: W09 | B11: 79094.28 | C11: 128925 | D11: 262635.79 | E11: 276594.94 | F11: 0.0532 | G11: 49059.4 | H11: =E11/G11 -> 5.6379601 | I11: =E11/32 -> 8643.5919 | J11: 0.54
A12: W10 | B12: 89003.15 | C12: 136693.53 | D12: 204447.96 | E12: 254721.9 | F12: 0.2459 | G12: 58536.18 | H12: =E12/G12 -> 4.3515293 | I12: =E12/32 -> 7960.0594 | J12: 0.59
A13: W11 | B13: 86718.5 | C13: 147013.19 | D13: 155715.91 | E13: 285332.49 | F13: 0.8324 | G13: 59855 | H13: =E13/G13 -> 4.7670619 | I13: =E13/32 -> 8916.6403 | J13: 0.63
A14: W12 | B14: 80100.16 | C14: 161552.92 | D14: 229340.03
A15: W13 | B15: 84645.12 | C15: 144737.76 | D15: 146517.87
A16: W14 | B16: 86681.61 | C16: 143125.14 | D16: 171618.72
A17: W15 | B17: 74512.4 | C17: 157705.67 | D17: 143872.02
A18: W16 | B18: 74192.53 | C18: 164823.99 | D18: 179689.87
A19: W17 | B19: 84733.62 | C19: 177324.95 | D19: 172109.29
A20: W18 | B20: 84201.74 | C20: 161978.93 | D20: 239699.14
A21: W19 | B21: 79536.47 | C21: 165397.81 | D21: 188420.94
A22: W20 | B22: 94029.92 | C22: 142485.68 | D22: 283371.93
A23: W21 | B23: 93860.58 | C23: 148690.66 | D23: 237449.68
A24: W22 | B24: 92044.97 | C24: 187398.86 | D24: 244199.32
A25: W23 | B25: 86816.03 | C25: 85814.9 | D25: 218365.28
... A38: W36 | B38: 124700.32 | C38: 133001.05 | D38: 280809.97
A39: W37 | C39: 165585.31 | D39: 174988.61
A40: W38 | B40: 5983.48 | C40: 156237.86 | D40: 233439.62
A41: W39 | B41: 329616.48 | C41: 198295.13 | D41: 174262.89
A42: W40 | B42: 130164.75 | C42: 234987.46 | D42: 257163.01
A43: W41 | B43: 113898.6 | C43: 172505.76 | D43: 213874.16
A44: W42 | B44: 106964.04 | C44: 182630.14 | D44: 180132.86
A45: W43 | B45: 105135.01 | C45: 225644.73 | D45: 205128.51
A46: W44 | B46: 113036.37 | C46: 251121.26 | D46: 257007.11
A47: W45 | B47: 119630.03 | C47: 222507.86 | D47: 217504.57
A48: W46 | B48: 125475.35 | C48: 190657.28 | D48: 246198.95
A49: W47 | B49: 129871.27 | C49: 180211.11 | D49: 255541.58
A50: W48 | B50: 115409.73 | C50: 232850.98 | D50: 172618.99
A51: W49 | B51: 105027.94 | C51: 225108.48 | D51: 328374.4
... A54: W52 | B54: 137427.87 | C54: 127610.55 | D54: 101605.31
A55: Totals | B55: =SUM(B3:B54) -> 5032553.7 | C55: =SUM(C3:C54) -> 8992075.4 | D55: =SUM(D3:D54) -> 10871993 | E55: =SUM(E3:E54) -> 2532777.9
...

Sheet Utilization Data
A1: Miles 2026 | B1: Revenue Per Mile 2026 | C1: Revenue Per Truck 2026 | D1: Utilization % | F1: Number of Trucks | G1: 32
A2: 26150.44 | B2: ='TFS Financial Data '!E2/'Utilization Data'!A2 -> 4.3938523 | C2: ='TFS Financial Data '!E2/$G$1 -> 3590.6616 | D2: 0.37
A3: 38641.74 | B3: ='TFS Financial Data '!E3/'Utilization Data'!A3 -> 4.5369693 | C3: ='TFS Financial Data '!E3/$G$1 -> 5478.6372 | D3: 0.52
A4: 44630.37 | B4: ='TFS Financial Data '!E4/'Utilization Data'!A4 -> 5.6876867 | C4: ='TFS Financial Data '!E4/$G$1 -> 7932.6112 | D4: 0.63
A5: 47958.86 | B5: ='TFS Financial Data '!E5/'Utilization Data'!A5 -> 4.8246624 | C5: ='TFS Financial Data '!E5/$G$1 -> 7230.7909 | D5: 0.71
A6: 46459.21 | B6: ='TFS Financial Data '!E6/'Utilization Data'!A6 -> 5.2487434 | C6: ='TFS Financial Data '!E6/$G$1 -> 7620.3897 | D6: 0.72
A7: 50715.14 | B7: ='TFS Financial Data '!E7/'Utilization Data'!A7 -> 4.6776838 | C7: ='TFS Financial Data '!E7/$G$1 -> 7413.4184 | D7: 0.79
A8: 52021.44 | B8: ='TFS Financial Data '!E8/'Utilization Data'!A8 -> 4.8054979 | C8: ='TFS Financial Data '!E8/$G$1 -> 7812.1538 | D8: 0.52
A9: 48223.569 | B9: ='TFS Financial Data '!E9/'Utilization Data'!A9 -> 4.3466578 | C9: ='TFS Financial Data '!E9/$G$1 -> 6550.3547 | D9: 0.55
A10: 49059.4 | B10: ='TFS Financial Data '!E10/'Utilization Data'!A10 -> 5.6379601 | C10: ='TFS Financial Data '!E10/$G$1 -> 8643.5919 | D10: 0.54
A11: 58536.18 | B11: ='TFS Financial Data '!E11/'Utilization Data'!A11 -> 4.3515293 | C11: ='TFS Financial Data '!E11/$G$1 -> 7960.0594 | D11: 0.59
A12: 59855 | B12: ='TFS Financial Data '!E12/'Utilization Data'!A12 -> 4.7670619 | C12: ='TFS Financial Data '!E12/$G$1 -> 8916.6403 | D12: 0.63

Sheet TFS Financial Data 
A1: Week # | B1: 2023 | C1: 2024 | D1: 2025 | E1: 2026 | F1: Previous Year % Change
A2: W01 | B2: 3718.75 | C2: 88296.61 | D2: 146998.6 | E2: 114901.17 | F2: -0.2184
A3: W02 | B3: 77590.58 | C3: 126978.65 | D3: 165902.35 | E3: 175316.39 | F3: 0.0567
A4: W03 | B4: 85440.26 | C4: 118982.09 | D4: 158181.09 | E4: 253843.56 | F4: 0.6048
A5: W04 | B5: 96081.51 | C5: 118903.61 | D5: 145399.18 | E5: 231385.31 | F5: 0.5914
A6: W05 | B6: 80816.82 | C6: 140190.75 | D6: 188231.53 | E6: 243852.47 | F6: 0.2955
A7: W06 | B7: 73017.07 | C7: 144552.29 | D7: 149220.7 | E7: 237229.39 | F7: 0.5898
A8: W07 | B8: 82108.13 | C8: 106451.51 | D8: 153156.54 | E8: 249988.92 | F8: 0.6322
A9: W08 | B9: 77806.5 | C9: 121868.36 | D9: 171482.25 | E9: 209611.35 | F9: 0.2224
A10: W09 | B10: 79094.28 | C10: 128925 | D10: 262635.79 | E10: 276594.94 | F10: 0.0532
A11: W10 | B11: 89003.15 | C11: 136693.53 | D11: 204447.96 | E11: 254721.9 | F11: 0.2459
A12: W11 | B12: 86718.5 | C12: 147013.19 | D12: 155715.91 | E12: 285332.49 | F12: 0.8324
A13: W12 | B13: 80100.16 | C13: 161552.92 | D13: 229340.03
A14: W13 | B14: 84645.12 | C14: 144737.76 | D14: 146517.87
A15: W14 | B15: 86681.61 | C15: 143125.14 | D15: 171618.72
A16: W15 | B16: 74512.4 | C16: 157705.67 | D16: 143872.02
A17: W16 | B17: 74192.53 | C17: 164823.99 | D17: 179689.87
A18: W17 | B18: 84733.62 | C18: 177324.95 | D18: 172109.29
A19: W18 | B19: 84201.74 | C19: 161978.93 | D19: 239699.14
A20: W19 | B20: 79536.47 | C20: 165397.81 | D20: 188420.94
A21: W20 | B21: 94029.92 | C21: 142485.68 | D21: 283371.93
A22: W21 | B22: 93860.58 | C22: 148690.66 | D22: 237449.68
A23: W22 | B23: 92044.97 | C23: 187398.86 | D23: 244199.32
A24: W23 | B24: 86816.03 | C24: 85814.9 | D24: 218365.28
... A37: W36 | B37: 124700.32 | C37: 133001.05 | D37: 280809.97
A38: W37 | C38: 165585.31 | D38: 174988.61
A39: W38 | B39: 5983.48 | C39: 156237.86 | D39: 233439.62
A40: W39 | B40: 329616.48 | C40: 198295.13 | D40: 174262.89
A41: W40 | B41: 130164.75 | C41: 234987.46 | D41: 257163.01
A42: W41 | B42: 113898.6 | C42: 172505.76 | D42: 213874.16
A43: W42 | B43: 106964.04 | C43: 182630.14 | D43: 180132.86
A44: W43 | B44: 105135.01 | C44: 225644.73 | D44: 205128.51
A45: W44 | B45: 113036.37 | C45: 251121.26 | D45: 257007.11
A46: W45 | B46: 119630.03 | C46: 222507.86 | D46: 217504.57
A47: W46 | B47: 125475.35 | C47: 190657.28 | D47: 246198.95
A48: W47 | B48: 129871.27 | C48: 180211.11 | D48: 255541.58
A49: W48 | B49: 115409.73 | C49: 232850.98 | D49: 172618.99
A50: W49 | B50: 105027.94 | C50: 225108.48 | D50: 328374.4
... A53: W52 | B53: 137427.87 | C53: 127610.55 | D53: 101605.31
A54: Totals | B54: =SUM(B2:B53) -> 5032553.7 | C54: =SUM(C2:C53) -> 8992075.4 | D54: =SUM(D2:D53) -> 10871993 | E54: =SUM(E2:E53) -> 2532777.9
